[0m20:15:58.948531 [debug] [MainThread]: Sending event: {'category': 'dbt', 'action': 'invocation', 'label': 'start', 'context': [<snowplow_tracker.self_describing_json.SelfDescribingJson object at 0x00000254B505AB50>, <snowplow_tracker.self_describing_json.SelfDescribingJson object at 0x00000254B8176850>, <snowplow_tracker.self_describing_json.SelfDescribingJson object at 0x00000254B8175E90>]}


============================== 20:15:58.948531 | 97bc8485-43cb-4272-84fe-d624b4fb0188 ==============================
[0m20:15:58.948531 [info ] [MainThread]: Running with dbt=1.9.3
[0m20:15:58.948531 [debug] [MainThread]: running dbt with arguments {'printer_width': '80', 'indirect_selection': 'eager', 'log_cache_events': 'False', 'write_json': 'True', 'partial_parse': 'True', 'cache_selected_only': 'False', 'profiles_dir': 'C:\\Users\\Atilla\\.dbt', 'fail_fast': 'False', 'warn_error': 'None', 'log_path': 'logs', 'debug': 'False', 'version_check': 'True', 'use_colors': 'True', 'use_experimental_parser': 'False', 'no_print': 'None', 'quiet': 'False', 'empty': 'None', 'log_format': 'default', 'introspect': 'True', 'invocation_command': 'dbt debug', 'warn_error_options': 'WarnErrorOptions(include=[], exclude=[])', 'target_path': 'None', 'static_parser': 'True', 'send_anonymous_usage_stats': 'True'}
[0m20:15:58.988725 [info ] [MainThread]: dbt version: 1.9.3
[0m20:15:58.988725 [info ] [MainThread]: python version: 3.11.8
[0m20:15:58.989725 [info ] [MainThread]: python path: C:\Users\Atilla\AppData\Local\Programs\Python\Python311\python.exe
[0m20:15:58.989725 [info ] [MainThread]: os info: Windows-10-10.0.19045-SP0
[0m20:16:00.894695 [info ] [MainThread]: Using profiles dir at C:\Users\Atilla\.dbt
[0m20:16:00.894695 [info ] [MainThread]: Using profiles.yml file at C:\Users\Atilla\.dbt\profiles.yml
[0m20:16:00.894695 [info ] [MainThread]: Using dbt_project.yml file at C:\Users\Atilla\Desktop\dbt_airflow\dbt_project.yml
[0m20:16:00.894695 [error] [MainThread]: Encountered an error:
Internal Error
  Profile should not be None if loading profile completed
[0m20:16:00.894695 [debug] [MainThread]: Command `dbt debug` failed at 20:16:00.894695 after 2.02 seconds
[0m20:16:00.894695 [debug] [MainThread]: Sending event: {'category': 'dbt', 'action': 'invocation', 'label': 'end', 'context': [<snowplow_tracker.self_describing_json.SelfDescribingJson object at 0x00000254B8185F50>, <snowplow_tracker.self_describing_json.SelfDescribingJson object at 0x00000254B81325D0>, <snowplow_tracker.self_describing_json.SelfDescribingJson object at 0x00000254B7E35450>]}
[0m20:16:00.894695 [debug] [MainThread]: Flushing usage events
[0m20:16:02.365863 [debug] [MainThread]: An error was encountered while trying to flush usage events
[0m00:46:53.381712 [debug] [MainThread]: Sending event: {'category': 'dbt', 'action': 'invocation', 'label': 'start', 'context': [<snowplow_tracker.self_describing_json.SelfDescribingJson object at 0x00000168D219BE90>, <snowplow_tracker.self_describing_json.SelfDescribingJson object at 0x00000168D219A6D0>, <snowplow_tracker.self_describing_json.SelfDescribingJson object at 0x00000168D2150DD0>]}


============================== 00:46:53.387359 | 16e6282b-02a6-4149-839a-0a004dffa74f ==============================
[0m00:46:53.387359 [info ] [MainThread]: Running with dbt=1.9.3
[0m00:46:53.387915 [debug] [MainThread]: running dbt with arguments {'printer_width': '80', 'indirect_selection': 'eager', 'log_cache_events': 'False', 'write_json': 'True', 'partial_parse': 'True', 'cache_selected_only': 'False', 'profiles_dir': 'C:\\Users\\Atilla\\.dbt', 'fail_fast': 'False', 'version_check': 'True', 'log_path': 'logs', 'debug': 'False', 'warn_error': 'None', 'use_colors': 'True', 'use_experimental_parser': 'False', 'empty': 'None', 'quiet': 'False', 'no_print': 'None', 'warn_error_options': 'WarnErrorOptions(include=[], exclude=[])', 'static_parser': 'True', 'invocation_command': 'dbt clean', 'log_format': 'default', 'target_path': 'None', 'introspect': 'True', 'send_anonymous_usage_stats': 'True'}
[0m00:46:53.388454 [error] [MainThread]: Encountered an error:
Runtime Error
  No dbt_project.yml found at expected path C:\Users\Atilla\Desktop\dbt_airflow\dbt_project.yml
  Verify that each entry within packages.yml (and their transitive dependencies) contains a file named dbt_project.yml
  
[0m00:46:53.389526 [debug] [MainThread]: Command `dbt clean` failed at 00:46:53.389526 after 0.09 seconds
[0m00:46:53.390069 [debug] [MainThread]: Sending event: {'category': 'dbt', 'action': 'invocation', 'label': 'end', 'context': [<snowplow_tracker.self_describing_json.SelfDescribingJson object at 0x00000168D2152590>, <snowplow_tracker.self_describing_json.SelfDescribingJson object at 0x00000168D21ABFD0>, <snowplow_tracker.self_describing_json.SelfDescribingJson object at 0x00000168D21A9C10>]}
[0m00:46:53.390626 [debug] [MainThread]: Flushing usage events
[0m00:46:54.501097 [debug] [MainThread]: An error was encountered while trying to flush usage events
[0m00:47:06.706351 [debug] [MainThread]: Sending event: {'category': 'dbt', 'action': 'invocation', 'label': 'start', 'context': [<snowplow_tracker.self_describing_json.SelfDescribingJson object at 0x0000024B3D6778D0>, <snowplow_tracker.self_describing_json.SelfDescribingJson object at 0x0000024B3D675E90>, <snowplow_tracker.self_describing_json.SelfDescribingJson object at 0x0000024B3D62B450>]}


============================== 00:47:06.710357 | eec4c6ce-5846-4bfa-8337-8391a15a2ba4 ==============================
[0m00:47:06.710357 [info ] [MainThread]: Running with dbt=1.9.3
[0m00:47:06.711352 [debug] [MainThread]: running dbt with arguments {'printer_width': '80', 'indirect_selection': 'eager', 'log_cache_events': 'False', 'write_json': 'True', 'partial_parse': 'True', 'cache_selected_only': 'False', 'profiles_dir': 'C:\\Users\\Atilla\\.dbt', 'debug': 'False', 'version_check': 'True', 'log_path': 'logs', 'fail_fast': 'False', 'warn_error': 'None', 'use_colors': 'True', 'use_experimental_parser': 'False', 'empty': 'None', 'quiet': 'False', 'no_print': 'None', 'log_format': 'default', 'introspect': 'True', 'warn_error_options': 'WarnErrorOptions(include=[], exclude=[])', 'invocation_command': 'dbt clean', 'target_path': 'None', 'static_parser': 'True', 'send_anonymous_usage_stats': 'True'}
[0m00:47:06.712349 [error] [MainThread]: Encountered an error:
Runtime Error
  No dbt_project.yml found at expected path C:\Users\Atilla\Desktop\dbt_airflow\dbt_project.yml
  Verify that each entry within packages.yml (and their transitive dependencies) contains a file named dbt_project.yml
  
[0m00:47:06.713360 [debug] [MainThread]: Command `dbt clean` failed at 00:47:06.713360 after 0.07 seconds
[0m00:47:06.713360 [debug] [MainThread]: Sending event: {'category': 'dbt', 'action': 'invocation', 'label': 'end', 'context': [<snowplow_tracker.self_describing_json.SelfDescribingJson object at 0x0000024B3D632650>, <snowplow_tracker.self_describing_json.SelfDescribingJson object at 0x0000024B369F5190>, <snowplow_tracker.self_describing_json.SelfDescribingJson object at 0x0000024B3D629F50>]}
[0m00:47:06.714352 [debug] [MainThread]: Flushing usage events
[0m00:47:07.614351 [debug] [MainThread]: An error was encountered while trying to flush usage events
